Workbook

Sheet LEEME
A1: TRASPASOS FADERMEX · BASE DE DATOS
A2: Mapa de este archivo: qué es cada hoja, quién la usa y qué significa cada color. Dueño: jaraujo@fadermex.com
A4: COLOR DE PESTAÑA
A5: CAT_… | C5: CATÁLOGO · La app LEE esta hoja · Solo administradores la editan
A6: CFG_… | C6: AJUSTES · La app LEE esta hoja · Solo administradores la editan
A7: RES_… | C7: RESULTADOS · La app ESCRIBE aquí sola · NO editar a mano
A8: REP_… | C8: REPORTE · Fórmulas automáticas · Solo consultar
A9: SYS_… | C9: SISTEMA · Uso interno de la app · NO TOCAR
A10: IMP_… | C10: IMPORTADO · Se copia solo desde tu archivo de Operaciones · NO editar
A12: REGLAS DE ORO
A13: • | C13: En todas las hojas: fila 1 = descripción, fila 2 = encabezados, datos desde la fila 3.
A14: • | C14: Al final de esta hoja está el diccionario de columnas: qué significa cada columna importante.
A15: • | C15: Hojas CAT_ y CFG_: aquí se agregan sucursales, áreas, personas, gestores y ajustes. La app toma los cambios sola.
A16: • | C16: Hojas RES_: las llena la app. No escribir, borrar ni ordenar a mano (usa filtros o una copia).
A17: • | C17: Prefijos de folio: únicos, de 2 a 5 letras (o con -RB para Rebotica). Un prefijo usado NO se cambia ni se reutiliza.
A18: • | C18: Para quitar un área o persona: Activo = NO. Nunca borres la fila, porque se pierde su historial.
A19: • | C19: Hoja SYS_Folios: la app lleva aquí el último número de cada prefijo. NO TOCAR.
A21: HOJA | B21: TIPO | C21: PARA QUÉ SIRVE | D21: QUIÉN LA EDITA
A22: CAT_Estatus | B22: CAT | C22: Estatus, colores y significado de cada uno. | D22: Administradores
A23: CAT_Sucursales | B23: CAT | C23: Lugares físicos (Oficinas, sucursales, Morelia, Botican). | D23: Administradores
A24: CAT_Areas | B24: CAT | C24: Áreas y subáreas con su prefijo de folio y correo. | D24: Administradores
A25: CAT_Equipos | B25: CAT | C25: Cada computadora fija a su área (PV o Rebotica). | D25: Administradores
A26: CAT_Personas | B26: CAT | C26: Personal y credenciales (incluye quien no tiene credencial). | D26: Administradores
A27: CAT_Gestores | B27: CAT | C27: Gestores y sus credenciales. | D27: Administradores
A28: CAT_Administradores | B28: CAT | C28: Las 3 cuentas con control total. | D28: Administradores
A29: CAT_Paqueterias | B29: CAT | C29: Paqueterías para Morelia. | D29: Administradores
A30: CAT_Motivos | B30: CAT | C30: Listas de motivos. | D30: Administradores
A31: CFG_Ajustes | B31: CFG | C31: Tiempos de sesión, alertas, etiqueta, pendientes. | D31: Administradores
A32: RES_Traspasos | B32: RES | C32: Estado actual de cada traspaso. | D32: Solo la app
... A43: SYS_Folios | B43: SYS | C43: Contadores de folios. | D43: Solo la app
A45: DICCIONARIO DE COLUMNAS
A46: HOJA | B46: COLUMNA | C46: QUÉ SIGNIFICA
A47: CAT_Estatus | B47: Clave | C47: Código interno. NO cambiar.
A48: CAT_Estatus | B48: Nombre en pantalla | C48: Texto que ve el usuario.
A49: CAT_Estatus | B49: Color texto (hex) | C49: Color del texto/punto del estatus en la app.
A50: CAT_Estatus | B50: Color fondo (hex) | C50: Color de fondo de la etiqueta de estatus en la app.
A51: CAT_Estatus | B51: Estado en app de gestores | C51: Qué Estado de APP_Traspasos (archivo de Operaciones) produce este estatus.
A52: CAT_Sucursales | B52: ID | C52: Código corto del lugar.
A53: CAT_Sucursales | B53: Tipo | C53: Oficinas / Sucursal / Foránea / Área independiente
A54: CAT_Sucursales | B54: Cómo se envía | C54: Gestoría, paquetería o entrega interna.
...

Sheet CAT_Estatus
A1: CAT_Estatus — CATÁLOGO · La app LEE esta hoja · Solo administradores la editan. Cada estatus, su color y lo que significa. Si cambias un color aquí, cambia en la app.
A2: Clave | B2: Nombre en pantalla | C2: Significado | D2: Quién lo provoca | E2: Color texto (hex) | F2: Color fondo (hex) | G2: Orden | H2: Muestra | I2: Estado en app de gestores
A3: NUEVO | B3: Nuevo traspaso | C3: Creado y etiquetado. Espera a que pase gestoría. | D3: Origen, al crearlo y escanear credencial | E3: 1F63D6 | F3: E2ECFF | G3: 1 | H3: Nuevo traspaso
A4: RECOLECTADO | B4: Recolectado por gestoría | C4: Va en tránsito con un gestor. | D4: Gestor con su celular o la sucursal escaneando la credencial del gestor | E4: 9A6400 | F4: FFF0CC | G4: 2 | H4: Recolectado por gestoría | I4: POR ENTREGAR
A5: EN_LOGISTICA | B5: En Logística | C5: Llegó a Logística (Oficinas): por enviar a Morelia o por distribuir. | D5: Logística al escanearlo | E5: 38559E | F5: E5EBF7 | G5: 3 | H5: En Logística
A6: PAQUETERIA | B6: Enviado por paquetería | C6: Va o viene de Morelia con número de guía. | D6: Logística (o Morelia) al capturar la guía | E6: 0B6C80 | F6: DAF2F7 | G6: 4 | H6: Enviado por paquetería
A7: ENTREGADO | B7: Entregado | C7: El destino lo escaneó y llegaron todos los bultos. | D7: Solo el destino al escanearlo | E7: 1B7F38 | F7: DFF3E5 | G7: 5 | H7: Entregado | I7: ENTREGADO (gestor) + escaneo del destino
A8: INCIDENCIA | B8: Recibido con incidencia | C8: Llegó, pero faltan bultos o llegó dañado. | D8: El destino al recibir incompleto | E8: C4440B | F8: FFE8DA | G8: 6 | H8: Recibido con incidencia | I8: NO ENTREGADO (gestor) → revisar
A9: UBICADO | B9: El traspaso está en… | C9: Se escaneó en un lugar que no es su destino. La columna Ubicación dice dónde está. | D9: Cualquier área que lo escanee por error | E9: 7036B8 | F9: EFE5FB | G9: 7 | H9: El traspaso está en…
A10: EXTRAVIADO | B10: Extraviado | C10: No aparece. Alerta automática por tiempo o marcado por un administrador. | D10: Administrador o alerta automática | E10: C8232D | F10: FDE6E7 | G10: 8 | H10: Extraviado
A11: ELIMINACION_SOLICITADA | B11: Eliminación solicitada | C11: Congelado: nadie lo puede mover hasta que responda un administrador. | D11: Origen al solicitar eliminar | E11: 4E5B67 | F11: E8ECF0 | G11: 9 | H11: Eliminación solicitada
A12: ELIMINADO | B12: Eliminado | C12: Lo eliminó un administrador. Ya no aparece en la app. | D12: Solo administradores | E12: FFFFFF | F12: 4E5B67 | G12: 10 | H12: Eliminado

Sheet CAT_Sucursales
A1: CAT_Sucursales — CATÁLOGO · La app LEE esta hoja · Solo administradores la editan. Lugares físicos. Dentro de cada uno están sus áreas (ver CAT_Areas).
A2: ID | B2: Nombre | C2: Tipo | D2: Cómo se envía | E2: Activa | F2: Notas
A3: OFI | B3: Oficinas | C3: Oficinas | D3: Interna (entrega a mano) | E3: SI | F3: Centro de distribución: Logística.
A4: NR | B4: Nueva Roma | C4: Sucursal | D4: Gestoría | E4: SI
A5: V | B5: Vertiz | C5: Sucursal | D5: Gestoría | E5: SI
A6: D | B6: Doctores | C6: Sucursal | D6: Gestoría | E6: SI
A7: C | B7: Coapa | C7: Sucursal | D7: Gestoría | E7: SI
A8: E | B8: Ecatepec | C8: Sucursal | D8: Gestoría | E8: SI
A9: M | B9: Morelia | C9: Foránea | D9: Paquetería vía Logística | E9: SI | F9: Todo lo que va o viene de Morelia lleva guía.
A10: BOT | B10: Botican | C10: Área independiente | D10: Gestoría | E10: SI | F10: Botican es un área propia, no pertenece a ninguna sucursal.

Sheet CAT_Areas
A1: CAT_Areas — CATÁLOGO · La app LEE esta hoja · Solo administradores la editan. Cada área o subárea que envía o recibe traspasos. Su prefijo es el inicio del folio (ej. NR-0001).
A2: Prefijo de folio | B2: Nombre del área | C2: Sucursal (ID) | D2: Correo de la cuenta | E2: Activa | F2: Notas
A3: DIR | B3: Dirección | C3: OFI | D3: por definir | E3: SI
A4: LOG | B4: Logística | C4: OFI | D4: por definir | E4: SI | F4: Recibe y envía todo lo de Morelia y distribuye en Oficinas.
A5: COM | B5: Compras | C5: OFI | D5: por definir | E5: SI
A6: MM | B6: Medicina Magistral | C6: OFI | D6: por definir | E6: SI
A7: EPV | B7: Encargada de PV | C7: OFI | D7: por definir | E7: SI
A8: GG | B8: Gerente General | C8: OFI | D8: por definir | E8: SI
A9: CONT | B9: Contabilidad | C9: OFI | D9: por definir | E9: SI
A10: FAC | B10: Facturación | C10: OFI | D10: por definir | E10: SI
A11: RH | B11: Recursos Humanos | C11: OFI | D11: por definir | E11: SI | F11: Oficinas tiene más áreas: agrégalas abajo con su propio prefijo.
A12: NR | B12: PV | C12: NR | D12: cuenta de Nueva Roma | E12: SI | F12: Misma cuenta que Rebotica. Salidas por área; entradas las recibe cualquiera de la sucursal.
A13: NR-RB | B13: Rebotica | C13: NR | D13: cuenta de Nueva Roma | E13: SI | F13: Computadora fija a Rebotica.
A14: V | B14: PV | C14: V | D14: cuenta de Vertiz | E14: SI
A15: V-RB | B15: Rebotica | C15: V | D15: cuenta de Vertiz | E15: SI
A16: D | B16: PV | C16: D | D16: cuenta de Doctores | E16: SI
A17: D-RB | B17: Rebotica | C17: D | D17: cuenta de Doctores | E17: SI
A18: C | B18: PV | C18: C | D18: cuenta de Coapa | E18: SI
A19: C-RB | B19: Rebotica | C19: C | D19: cuenta de Coapa | E19: SI
A20: E | B20: PV | C20: E | D20: cuenta de Ecatepec | E20: SI
A21: E-RB | B21: Rebotica | C21: E | D21: cuenta de Ecatepec | E21: SI
A22: M | B22: PV | C22: M | D22: cuenta de Morelia | E22: SI
A23: M-RB | B23: Rebotica | C23: M | D23: cuenta de Morelia | E23: SI
A24: BOT | B24: Botican | C24: BOT | D24: por definir (producción Botican) | E24: SI | F24: Área independiente con su propia computadora y correo.

Sheet CAT_Equipos
A1: CAT_Equipos — CATÁLOGO · La app LEE esta hoja · Solo administradores la editan. Cada computadora queda fija a un área para las SALIDAS (crear y entregar a gestor). Las ENTRADAS las puede recibir cualquier computadora de la sucursal; la app indica PARA PV o PARA REBOTICA.
A2: ID equipo | B2: Sucursal | C2: Área (prefijo) | D2: Descripción | E2: Activo
A3: NR-PV | B3: Nueva Roma | C3: NR | D3: Computadora de PV | E3: SI
A4: NR-RB | B4: Nueva Roma | C4: NR-RB | D4: Computadora de Rebotica | E4: SI
A5: V-PV | B5: Vertiz | C5: V | D5: Computadora de PV | E5: SI
A6: V-RB | B6: Vertiz | C6: V-RB | D6: Computadora de Rebotica | E6: SI
A7: D-PV | B7: Doctores | C7: D | D7: Computadora de PV | E7: SI
A8: D-RB | B8: Doctores | C8: D-RB | D8: Computadora de Rebotica | E8: SI
A9: C-PV | B9: Coapa | C9: C | D9: Computadora de PV | E9: SI
A10: C-RB | B10: Coapa | C10: C-RB | D10: Computadora de Rebotica | E10: SI
A11: E-PV | B11: Ecatepec | C11: E | D11: Computadora de PV | E11: SI
A12: E-RB | B12: Ecatepec | C12: E-RB | D12: Computadora de Rebotica | E12: SI
A13: M-PV | B13: Morelia | C13: M | D13: Computadora de PV | E13: SI
... A15: BOT | B15: Botican | C15: BOT | D15: Computadora de Botican | E15: SI

Sheet CAT_Personas
A1: CAT_Personas — CATÁLOGO · La app LEE esta hoja · Solo administradores la editan. Personal que crea traspasos (aprox. 60 credenciales). Quien aún no tiene credencial va con Credencial vacía y Tiene credencial = NO.
A2: No. empleado | B2: Nombre completo | C2: Código de credencial | D2: Área (prefijo) | E2: Tiene credencial | F2: Activo | G2: Alta | H2: Notas

Sheet CAT_Gestores
A1: CAT_Gestores — CATÁLOGO · La app LEE esta hoja · Solo administradores la editan. Gestores de traspasos. Su credencial sirve para registrar la salida cuando no traen celular.
A2: Código de credencial | B2: Nombre completo | C2: Celular | D2: Vehículo | E2: Activo

Sheet CAT_Administradores
A1: CAT_Administradores — CATÁLOGO · La app LEE esta hoja · Solo administradores la editan. Cuentas con control total (editar, mover, cambiar estatus, eliminar).
A2: Correo | B2: Nombre | C2: Rol | D2: Activo
A3: jaraujo@fadermex.com | C3: Dueño | D3: SI
A4: Oramirez@fadermex.com | C4: Administrador | D4: SI
A5: sistemasfed@fadermex.com | C5: Administrador | D5: SI

Sheet CAT_Paqueterias
A1: CAT_Paqueterias — CATÁLOGO · La app LEE esta hoja · Solo administradores la editan. Paqueterías para envíos a/desde Morelia.
A2: Paquetería | B2: Activa
A3: Estafeta | B3: SI
A4: DHL | B4: SI
A5: FedEx | B5: SI
A6: Paquetexpress | B6: SI

Sheet CAT_Motivos
A1: CAT_Motivos — CATÁLOGO · La app LEE esta hoja · Solo administradores la editan. Opciones que aparecen en listas de la app.
A2: Tipo | B2: Motivo | C2: Activo
A3: REIMPRESION | B3: Etiqueta dañada | C3: SI
A4: REIMPRESION | B4: No imprimió | C4: SI
A5: REIMPRESION | B5: Se cayó o despegó | C5: SI
A6: REIMPRESION | B6: Otro | C6: SI
A7: ELIMINACION | B7: Traspaso duplicado | C7: SI
A8: ELIMINACION | B8: Destino equivocado | C8: SI
A9: ELIMINACION | B9: Ya no se envía | C9: SI
A10: ELIMINACION | B10: Otro | C10: SI
A11: INCIDENCIA | B11: Faltan bultos | C11: SI
A12: INCIDENCIA | B12: Llegó dañado | C12: SI
A13: INCIDENCIA | B13: Otro | C13: SI

Sheet CFG_Ajustes
A1: CFG_Ajustes — AJUSTES · La app LEE esta hoja · Solo administradores la editan. Parámetros de la app. Cambia solo la columna Valor.
A2: Parámetro | B2: Valor | C2: Qué hace
A3: sesion_horas_sucursal | B3: 12 | C3: Horas antes de cerrar sesión en computadoras de sucursales y áreas.
A4: sesion_horas_admin | B4: 12 | C4: Horas antes de cerrar sesión de administradores.
A5: alerta_sin_recolectar_horas | B5: 4 | C5: Avisar si un traspaso nuevo no se recolecta en este tiempo.
A6: alerta_transito_horas | B6: 24 | C6: Avisar si un traspaso lleva este tiempo con gestoría sin entregarse.
A7: alerta_paqueteria_dias | B7: 4 | C7: Avisar si un envío por paquetería tarda más de estos días.
A8: revisar_avisos_cada_seg | B8: 45 | C8: Cada cuántos segundos la app revisa si hay traspasos nuevos para el área.
A9: folio_digitos | B9: 4 | C9: Dígitos del consecutivo del folio (NR-0001).
A10: etiqueta_ancho_mm | B10: 62 | C10: Ancho de la etiqueta. PENDIENTE confirmar con el modelo de la etiquetadora.
A11: etiqueta_alto_mm | B11: 100 | C11: Alto de la etiqueta. PENDIENTE confirmar.
A12: etiquetadora_modelo | B12: PENDIENTE | C12: Modelo de las etiquetadoras Brother.
A13: logo_empresa | B13: PENDIENTE | C13: Imagen/logo de la empresa para la app y las etiquetas.
A14: url_archivo_operaciones | B14: PENDIENTE | C14: Pega aquí el link de tu archivo de Operaciones (el que tiene APP_Traspasos). De ahí se jalan las recolecciones de los gestores.

Sheet RES_Traspasos
A1: RES_Traspasos — RESULTADOS · La app ESCRIBE aquí sola · NO editar a mano. Un renglón por traspaso, siempre con su estado más reciente. El color de cada fila es el de su estatus.
A2: Folio | B2: Fecha creación | C2: Hora | D2: Origen (prefijo) | E2: Origen | F2: Destino (prefijo) | G2: Destino | H2: Descripción | I2: Bultos | J2: Creado por | K2: Credencial | L2: Sin credencial | M2: Estatus | N2: Ubicación actual | O2: Ruta | P2: Gestor | Q2: Fecha recolección | R2: Paquetería | S2: Guía | T2: Fecha entrega | U2: Recibido por | V2: Bultos recibidos | W2: Reimpresiones | X2: Eliminación solicitada | Y2: Última actualización

Sheet RES_Movimientos
A1: RES_Movimientos — RESULTADOS · La app ESCRIBE aquí sola · NO editar a mano. Bitácora: un renglón por cada cosa que le pasa a un traspaso. Así se arma la línea de tiempo.
A2: ID | B2: Fecha | C2: Hora | D2: Folio | E2: Acción | F2: Estatus anterior | G2: Estatus nuevo | H2: Dónde ocurrió (área) | I2: Persona | J2: Credencial | K2: Medio | L2: Equipo | M2: Detalle

Sheet RES_Escaneos
A1: RES_Escaneos — RESULTADOS · La app ESCRIBE aquí sola · NO editar a mano. Cada escaneo o folio tecleado, incluidos los errores. Sirve para detectar errores humanos.
A2: Fecha | B2: Hora | C2: Área | D2: Equipo | E2: Modo | F2: Texto escaneado | G2: Resultado | H2: Mensaje mostrado

Sheet RES_Etiquetas
A1: RES_Etiquetas — RESULTADOS · La app ESCRIBE aquí sola · NO editar a mano. Cada etiqueta impresa y reimpresa.
A2: Fecha | B2: Hora | C2: Folio | D2: Bulto | E2: Impresión | F2: Persona | G2: Motivo

Sheet RES_Solicitudes
A1: RES_Solicitudes — RESULTADOS · La app ESCRIBE aquí sola · NO editar a mano. Solicitudes de eliminación y su respuesta.
A2: ID | B2: Fecha | C2: Folio | D2: Solicitó | E2: Área | F2: Motivo | G2: Estado | H2: Administrador | I2: Fecha respuesta | J2: Comentario

Sheet RES_Administracion
A1: RES_Administracion — RESULTADOS · La app ESCRIBE aquí sola · NO editar a mano. Todo lo que hacen los administradores: ediciones, movimientos, eliminaciones, altas.
A2: Fecha | B2: Hora | C2: Administrador | D2: Acción | E2: Objeto | F2: Antes | G2: Después | H2: Motivo

Sheet RES_Sesiones
A1: RES_Sesiones — RESULTADOS · La app ESCRIBE aquí sola · NO editar a mano. Entradas y salidas de cuentas.
A2: Fecha | B2: Hora | C2: Cuenta | D2: Equipo | E2: Evento | F2: Dispositivo

Sheet RES_Avisos
A1: RES_Avisos — RESULTADOS · La app ESCRIBE aquí sola · NO editar a mano. Avisos enviados a cada área (traspaso nuevo, va en camino, alertas).
A2: Fecha | B2: Hora | C2: Para (área) | D2: Folio | E2: Mensaje | F2: Visto

Sheet IMP_Recolecciones
A1: IMP_Recolecciones — IMPORTADO · Se copia solo desde tu archivo de Operaciones · NO editar. Copia en vivo de la hoja APP_Traspasos de tu archivo de Operaciones (lo que escanean los gestores). La app la cruza por Folio y actualiza RES_Traspasos.
A2: Folio | B2: FechaRecoleccion | C2: Gestor | D2: Vehiculo | E2: Origen | F2: Destino | G2: Area | H2: Contenido | I2: Estado | J2: URLFotoRecoleccion
A3: =IFERROR(IMPORTRANGE(CFG_Ajustes!B14,"APP_Traspasos!A2:J"),"Pega el link del archivo de Operaciones en CFG_Ajustes (url_archivo_operaciones) y luego da clic aquí en Permitir acceso")

Sheet IMP_NoRegistrados
A1: IMP_NoRegistrados — IMPORTADO · Se copia solo desde tu archivo de Operaciones · NO editar. Folios que escaneó un gestor pero NO existen en este sistema (mal escaneados, o traspasos hechos fuera del sistema). Revisar.
A2: Folio | B2: FechaRecoleccion | C2: Gestor | D2: Estado
A3: =IFERROR(FILTER({IMP_Recolecciones!A3:C,IMP_Recolecciones!I3:I},IMP_Recolecciones!A3:A<>"",ISNA(MATCH(IMP_Recolecciones!A3:A,RES_Traspasos!A3:A,0))),"Sin folios desconocidos")

Sheet REP_Resumen
A1: REP_Resumen — REPORTE · Fórmulas automáticas · Solo consultar. Conteos automáticos a partir de RES_Traspasos.
A2: Estatus | B2: Nombre | C2: Cantidad
A3: NUEVO | B3: Nuevo traspaso | C3: =COUNTIF(RES_Traspasos!$M$3:$M,"NUEVO")
A4: RECOLECTADO | B4: Recolectado por gestoría | C4: =COUNTIF(RES_Traspasos!$M$3:$M,"RECOLECTADO")
A5: EN_LOGISTICA | B5: En Logística | C5: =COUNTIF(RES_Traspasos!$M$3:$M,"EN_LOGISTICA")
A6: PAQUETERIA | B6: Enviado por paquetería | C6: =COUNTIF(RES_Traspasos!$M$3:$M,"PAQUETERIA")
A7: ENTREGADO | B7: Entregado | C7: =COUNTIF(RES_Traspasos!$M$3:$M,"ENTREGADO")
A8: INCIDENCIA | B8: Recibido con incidencia | C8: =COUNTIF(RES_Traspasos!$M$3:$M,"INCIDENCIA")
A9: UBICADO | B9: El traspaso está en… | C9: =COUNTIF(RES_Traspasos!$M$3:$M,"UBICADO")
A10: EXTRAVIADO | B10: Extraviado | C10: =COUNTIF(RES_Traspasos!$M$3:$M,"EXTRAVIADO")
A11: ELIMINACION_SOLICITADA | B11: Eliminación solicitada | C11: =COUNTIF(RES_Traspasos!$M$3:$M,"ELIMINACION_SOLICITADA")
A12: ELIMINADO | B12: Eliminado | C12: =COUNTIF(RES_Traspasos!$M$3:$M,"ELIMINADO")
A13: TOTAL | C13: =SUM(C3:C12)
A15: Por área de origen
A16: Área | C16: Traspasos
A17: DIR | B17: Dirección | C17: =COUNTIF(RES_Traspasos!$D$3:$D,"DIR")
A18: LOG | B18: Logística | C18: =COUNTIF(RES_Traspasos!$D$3:$D,"LOG")
A19: COM | B19: Compras | C19: =COUNTIF(RES_Traspasos!$D$3:$D,"COM")
A20: MM | B20: Medicina Magistral | C20: =COUNTIF(RES_Traspasos!$D$3:$D,"MM")
A21: EPV | B21: Encargada de PV | C21: =COUNTIF(RES_Traspasos!$D$3:$D,"EPV")
A22: GG | B22: Gerente General | C22: =COUNTIF(RES_Traspasos!$D$3:$D,"GG")
A23: CONT | B23: Contabilidad | C23: =COUNTIF(RES_Traspasos!$D$3:$D,"CONT")
A24: FAC | B24: Facturación | C24: =COUNTIF(RES_Traspasos!$D$3:$D,"FAC")
A25: RH | B25: Recursos Humanos | C25: =COUNTIF(RES_Traspasos!$D$3:$D,"RH")
A26: NR | B26: PV | C26: =COUNTIF(RES_Traspasos!$D$3:$D,"NR")
A27: NR-RB | B27: Rebotica | C27: =COUNTIF(RES_Traspasos!$D$3:$D,"NR-RB")
A28: V | B28: PV | C28: =COUNTIF(RES_Traspasos!$D$3:$D,"V")
A29: V-RB | B29: Rebotica | C29: =COUNTIF(RES_Traspasos!$D$3:$D,"V-RB")
A30: D | B30: PV | C30: =COUNTIF(RES_Traspasos!$D$3:$D,"D")
A31: D-RB | B31: Rebotica | C31: =COUNTIF(RES_Traspasos!$D$3:$D,"D-RB")
A32: C | B32: PV | C32: =COUNTIF(RES_Traspasos!$D$3:$D,"C")
A33: C-RB | B33: Rebotica | C33: =COUNTIF(RES_Traspasos!$D$3:$D,"C-RB")
A34: E | B34: PV | C34: =COUNTIF(RES_Traspasos!$D$3:$D,"E")
A35: E-RB | B35: Rebotica | C35: =COUNTIF(RES_Traspasos!$D$3:$D,"E-RB")
A36: M | B36: PV | C36: =COUNTIF(RES_Traspasos!$D$3:$D,"M")
A37: M-RB | B37: Rebotica | C37: =COUNTIF(RES_Traspasos!$D$3:$D,"M-RB")
A38: BOT | B38: Botican | C38: =COUNTIF(RES_Traspasos!$D$3:$D,"BOT")

Sheet SYS_Folios
A1: SYS_Folios — SISTEMA · Uso interno de la app · NO TOCAR. Último consecutivo usado por cada prefijo. La app lo actualiza con candado para que nunca se repita un folio.
A2: Prefijo | B2: Último número | C2: Actualizado
A3: DIR | B3: 0
A4: LOG | B4: 0
A5: COM | B5: 0
A6: MM | B6: 0
A7: EPV | B7: 0
A8: GG | B8: 0
A9: CONT | B9: 0
A10: FAC | B10: 0
A11: RH | B11: 0
A12: NR | B12: 0
A13: NR-RB | B13: 0
A14: V | B14: 0
... A24: BOT | B24: 0
